<?xml version = "1.0" ?>
<robot name = "my_robot" xmlns:xacro = "http://www.ros.org/wiki/xacro">
  <!--dummy link-->
  <link name = "base_link">
  </link>

 <!-- first link-->
  <link name = "chassis">
    <pose>0 0 0 0 0 0</pose>

    <inertial>
      <mass value = "5"/>
      <origin rpy = "0 0 0" xyz = "0 0 0.1"/>
      <inertia ixx="1.0" ixy="0.0" ixz="0.0"
        iyy="1.0" iyz="0.0"
        izz="1.0"/>
    </inertial>

    <collision name = "collision">
      <geometry>
        <box size = "1 1 2"/>
      </geometry>
    </collision>

    <visual name = "visual">
      <origin rpy = "0 0 0" xyz = "0 0 0"/>
      <geometry>
        <box size = "1 1 2"/>
      </geometry>
    </visual>
  </link>

  <link name = "arm">
    <pose>0 0 0 0 0 0</pose>

    <inertial>
      <mass value = "5"/>
      <origin rpy = "0 0 0" xyz = "0 0 0"/>
      <inertia ixx="1.0" ixy="0.0" ixz="0.0"
        iyy="1.0" iyz="0.0"
        izz="1.0"/>
    </inertial>

    <collision name = "collision">
      <origin rpy = "0 0 0" xyz = "0 0 0.5"/>
      <geometry>
        <box size = "0.2 0.2 1"/>
      </geometry>
    </collision>

    <visual name = "visual">
      <origin rpy = "0 0 0" xyz = "0 0 0.5"/>
      <geometry>
        <box size = "0.2 0.2 1"/>
      </geometry>
    </visual>

  </link>

  <joint name = "first_joint" type = "fixed">
    <origin xyz = "0 0 0" rpy = "0 0 0"/>
    <parent link = "base_link"/>
    <child link = "chassis"/>
  </joint>

  <joint name = "joint1" type = "continuous">
  <origin xyz = "1 0 2" rpy = "0 0 0"/>
  <axis rpy="0 0 0" xyz="0 3 0"/>
  <parent link = "chassis"/>
  <child link = "arm"/>
  </joint>



</robot>
